<?xml version="1.0"?>
<robot name="quaro-leg" xmlns:xacro="http://ros.org/wiki/xacro">
  <xacro:property name="effor" value="1.47"/>
  <xacro:property name="zero" value="0.0"/>
  <xacro:property name="velocity" value="0.1"/>

  <xacro:macro name="leg" params="n xyz rpy parent">
  <!-- Joint A1 or B1 -->
  <joint name="leg${n}_joint1" type="revolute">
    <parent link="${parent}"/>
    <child link="leg${n}_link1"/>
    <origin xyz="${xyz}" rpy="${rpy}"/>
    <axis xyz="0 0 1"/>
    <limit effort="100.0" velocity="1.0" lower="-${2*pi/3}" upper="${2*pi/3}"/>
  </joint>

  <link name="leg${n}_link1">
    <visual>
      <geometry>
        <box size="0.1 0.4 0.1"/>
      </geometry>
      <origin xyz="0.0 0.2 0.0" rpy="0 0 0"/>
    </visual>
  </link>

  <joint name="leg${n}_joint2" type="revolute">
    <parent link="leg${n}_link1"/>
    <child link="leg${n}_link2"/>
    <origin xyz="0.0 0.6 0.0" rpy="0 0 0"/>
    <axis xyz="1 0 0"/>
    <limit effort="100.0" velocity="1.0" lower="-${2*pi/3}" upper="${2*pi/3}"/>
  </joint>

  <link name="leg${n}_link2">
    <visual>
      <geometry>
        <box size="0.1 0.4 0.1"/>
      </geometry>
      <origin xyz="0.0 0.2 0.0" rpy="0 0 0"/>
    </visual>
  </link>

  <!-- Joint A3 or B3 -->
  <joint name="leg${n}_joint3" type="revolute">
    <parent link="leg${n}_link2"/>
    <child link="leg${n}_link3"/>
    <origin xyz="0.0 0.6 0.0" rpy="0 0 0"/>
    <axis xyz="1 0 0"/>
    <limit effort="100.0" velocity="1.0" lower="-${2*pi/3}" upper="${2*pi/3}"/>
  </joint>
  <link name="leg${n}_link3">
    <visual>
      <geometry>
        <box size="0.1 0.4 0.1"/>
      </geometry>
      <origin xyz="0.0 0.2 0.0" rpy="0 0 0"/>
    </visual>
  </link>
  </xacro:macro>
</robot>

